Workbook
Name Slicer_CALORIES_BURNT1: #N/A
Name Slicer_DAY1: #N/A
Name Slicer_SLEEP_hrs: #N/A
Name Slicer_STATUS: #N/A
Name Slicer_WORKOUT_TYPE: #N/A

Sheet DAILY WORKOUT LOG
A1: FITNESS TRACKER
A2: NAME | B2: DATE | C2: DAY | D2: STEPS | E2: MOOD | F2: WORKOUT TYPE | G2: CALORIES BURNT/MIN | H2: DURATION | I2: CALORIES BURNT | J2: SLEEP(hrs) | K2: WATER(L) | L2: WEIGHT(Kg) | M2: HEIGHT(Cm) | N2: BMI | O2: CATEGORY | P2: STATUS
A3: AADHI | B3: 45833 | C3: =TEXT(B3,"dddd") -> Wednesday | D3: 10000 | E3: HAPPY | F3: RUNNING | G3: 8 | H3: 40 | I3: =IF(ISBLANK(Table1[[#This Row],[DURATION]])," ",G3*H3) -> 320 | J3: 6.5 | K3: 2 | L3: 52 | M3: 155 | N3: =ROUND(L3/((M3/100)^2),0) -> 22 | O3: =IF(N3<18,"UNDERWEIGHT",IF(N3<25,"NORMAL",IF(N3<30,"OVERWEIGHT","OBESE"))) -> NORMAL | P3: =IF(D3>=7000,"ACTIVE","IN ACTIVE") -> ACTIVE
A4: AARAV | B4: 45833 | C4: =TEXT(B4,"dddd") -> Wednesday | D4: 12500 | E4: ENERGETIC | F4: WALKING | G4: 7 | H4: 50 | I4: =IF(ISBLANK(Table1[[#This Row],[DURATION]])," ",G4*H4) -> 350 | J4: 7.2 | K4: 2.5 | L4: 82 | M4: 175 | N4: =ROUND(L4/((M4/100)^2),0) -> 27 | O4: =IF(N4<18,"UNDERWEIGHT",IF(N4<25,"NORMAL",IF(N4<30,"OVERWEIGHT","OBESE"))) -> OVERWEIGHT | P4: =IF(D4>=7000,"ACTIVE","IN ACTIVE") -> ACTIVE
A5: AISHU | B5: 45833 | C5: =TEXT(B5,"dddd") -> Wednesday | D5: 5000 | E5: TIRED | F5: YOGA | G5: 8 | H5: 60 | I5: =IF(ISBLANK(Table1[[#This Row],[DURATION]])," ",G5*H5) -> 480 | J5: 6 | K5: 1.8 | L5: 56 | M5: 160 | N5: =ROUND(L5/((M5/100)^2),0) -> 22 | O5: =IF(N5<18,"UNDERWEIGHT",IF(N5<25,"NORMAL",IF(N5<30,"OVERWEIGHT","OBESE"))) -> NORMAL | P5: =IF(D5>=7000,"ACTIVE","IN ACTIVE") -> IN ACTIVE
A6: AMAN | B6: 45833 | C6: =TEXT(B6,"dddd") -> Wednesday | D6: 7000 | E6: LAZY | F6: CYCLING | G6: 6 | H6: 30 | I6: =IF(ISBLANK(Table1[[#This Row],[DURATION]])," ",G6*H6) -> 180 | J6: 7 | K6: 2.3 | L6: 79 | M6: 175 | N6: =ROUND(L6/((M6/100)^2),0) -> 26 | O6: =IF(N6<18,"UNDERWEIGHT",IF(N6<25,"NORMAL",IF(N6<30,"OVERWEIGHT","OBESE"))) -> OVERWEIGHT | P6: =IF(D6>=7000,"ACTIVE","IN ACTIVE") -> ACTIVE
A7: ANANYA | B7: 45833 | C7: =TEXT(B7,"dddd") -> Wednesday | D7: 10260 | E7: HAPPY | F7: TREAD MILL | G7: 7 | H7: 20 | I7: =IF(ISBLANK(Table1[[#This Row],[DURATION]])," ",G7*H7) -> 140 | J7: 6.8 | K7: 2.1 | L7: 63 | M7: 172 | N7: =ROUND(L7/((M7/100)^2),0) -> 21 | O7: =IF(N7<18,"UNDERWEIGHT",IF(N7<25,"NORMAL",IF(N7<30,"OVERWEIGHT","OBESE"))) -> NORMAL | P7: =IF(D7>=7000,"ACTIVE","IN ACTIVE") -> ACTIVE
A8: ANU | B8: 45833 | C8: =TEXT(B8,"dddd") -> Wednesday | D8: 3700 | E8: LAZY | F8: STRETCHING | G8: 6 | H8: 48 | I8: =IF(ISBLANK(Table1[[#This Row],[DURATION]])," ",G8*H8) -> 288 | J8: 7.2 | K8: 2.2 | L8: 74 | M8: 132 | N8: =ROUND(L8/((M8/100)^2),0) -> 42 | O8: =IF(N8<18,"UNDERWEIGHT",IF(N8<25,"NORMAL",IF(N8<30,"OVERWEIGHT","OBESE"))) -> OBESE | P8: =IF(D8>=7000,"ACTIVE","IN ACTIVE") -> IN ACTIVE
A9: ARCHANA | B9: 45833 | C9: =TEXT(B9,"dddd") -> Wednesday | D9: 12600 | E9: ENERGETIC | F9: GYM | G9: 10 | H9: 45 | I9: =IF(ISBLANK(Table1[[#This Row],[DURATION]])," ",G9*H9) -> 450 | J9: 7.4 | K9: 2.7 | L9: 48 | M9: 158 | N9: =ROUND(L9/((M9/100)^2),0) -> 19 | O9: =IF(N9<18,"UNDERWEIGHT",IF(N9<25,"NORMAL",IF(N9<30,"OVERWEIGHT","OBESE"))) -> NORMAL | P9: =IF(D9>=7000,"ACTIVE","IN ACTIVE") -> ACTIVE
A10: ARYAN | B10: 45833 | C10: =TEXT(B10,"dddd") -> Wednesday | D10: 8900 | E10: TIRED | F10: WEIGHT LIFTING | G10: 6 | H10: 55 | I10: =IF(ISBLANK(Table1[[#This Row],[DURATION]])," ",G10*H10) -> 330 | J10: 5.9 | K10: 1.9 | L10: 48 | M10: 180 | N10: =ROUND(L10/((M10/100)^2),0) -> 15 | O10: =IF(N10<18,"UNDERWEIGHT",IF(N10<25,"NORMAL",IF(N10<30,"OVERWEIGHT","OBESE"))) -> UNDERWEIGHT | P10: =IF(D10>=7000,"ACTIVE","IN ACTIVE") -> ACTIVE
A11: BANU | B11: 45833 | C11: =TEXT(B11,"dddd") -> Wednesday | D11: 7000 | E11: LAZY | F11: SQUADS | G11: 5 | H11: 65 | I11: =IF(ISBLANK(Table1[[#This Row],[DURATION]])," ",G11*H11) -> 325 | J11: 6.7 | K11: 2.4 | L11: 85 | M11: 150 | N11: =ROUND(L11/((M11/100)^2),0) -> 38 | O11: =IF(N11<18,"UNDERWEIGHT",IF(N11<25,"NORMAL",IF(N11<30,"OVERWEIGHT","OBESE"))) -> OBESE | P11: =IF(D11>=7000,"ACTIVE","IN ACTIVE") -> ACTIVE
A12: BHUVANA | B12: 45834 | C12: =TEXT(B12,"dddd") -> Thursday | D12: 6600 | E12: HAPPY | F12: STRETCHING | G12: 5 | H12: 25 | I12: =IF(ISBLANK(Table1[[#This Row],[DURATION]])," ",G12*H12) -> 125 | J12: 6.8 | K12: 2 | L12: 60 | M12: 178 | N12: =ROUND(L12/((M12/100)^2),0) -> 19 | O12: =IF(N12<18,"UNDERWEIGHT",IF(N12<25,"NORMAL",IF(N12<30,"OVERWEIGHT","OBESE"))) -> NORMAL | P12: =IF(D12>=7000,"ACTIVE","IN ACTIVE") -> IN ACTIVE
A13: CHARU | B13: 45834 | C13: =TEXT(B13,"dddd") -> Thursday | D13: 5500 | E13: ENERGETIC | F13: PUSHUPS | G13: 9 | H13: 25 | I13: =IF(ISBLANK(Table1[[#This Row],[DURATION]])," ",G13*H13) -> 225 | J13: 6.5 | K13: 1.2 | L13: 75 | M13: 162 | N13: =ROUND(L13/((M13/100)^2),0) -> 29 | O13: =IF(N13<18,"UNDERWEIGHT",IF(N13<25,"NORMAL",IF(N13<30,"OVERWEIGHT","OBESE"))) -> OVERWEIGHT | P13: =IF(D13>=7000,"ACTIVE","IN ACTIVE") -> IN ACTIVE
A14: DEV | B14: 45834 | C14: =TEXT(B14,"dddd") -> Thursday | D14: 11240 | E14: TIRED | F14: TREAD MILL | G14: 7 | H14: 50 | I14: =IF(ISBLANK(Table1[[#This Row],[DURATION]])," ",G14*H14) -> 350 | J14: 7.1 | K14: 2.2 | L14: 50 | M14: 170 | N14: =ROUND(L14/((M14/100)^2),0) -> 17 | O14: =IF(N14<18,"UNDERWEIGHT",IF(N14<25,"NORMAL",IF(N14<30,"OVERWEIGHT","OBESE"))) -> UNDERWEIGHT | P14: =IF(D14>=7000,"ACTIVE","IN ACTIVE") -> ACTIVE
... A61: YUVI | B61: 45838 | C61: =TEXT(B61,"dddd") -> Monday | D61: 9000 | E61: ENERGETIC | F61: SQUADS | G61: 5 | H61: 25 | I61: =IF(ISBLANK(Table1[[#This Row],[DURATION]])," ",G61*H61) -> 125 | J61: 3.9 | K61: 1.8 | L61: 85 | M61: 110 | N61: =ROUND(L61/((M61/100)^2),0) -> 70 | O61: =IF(N61<18,"UNDERWEIGHT",IF(N61<25,"NORMAL",IF(N61<30,"OVERWEIGHT","OBESE"))) -> OBESE | P61: =IF(D61>=7000,"ACTIVE","IN ACTIVE") -> ACTIVE

Sheet MEMBER ANALYSIS
A1: WHO BURNT MOST CALORIES
J2: TOP 3 CALORIES BURNER
C3: =INDEX('DAILY WORKOUT LOG'!A3:A61,MATCH(MAX('DAILY WORKOUT LOG'!I3:I61),'DAILY WORKOUT LOG'!I3:I61,0)) -> KARTHICK
K4: NAMES | L4: CALORIES BURNT | M4: STEPS | N4: WORKOUT DURATION | O4: WATER(L)
A5: HOW MANY STEPS ARCHANA WALKED | K5: KARTHICK | L5: 720 | M5: 12400 | N5: 72 | O5: 2
K6: PRABHA | L6: 700 | M6: 11900 | N6: 70 | O6: 2.1
B7: ARCHANA | C7: =VLOOKUP(B7,'DAILY WORKOUT LOG'!A:P,4,FALSE) -> 12600 | K7: JILLU | L7: 620 | M7: 12800 | N7: 85 | O7: 4.1
K8: VICKY | L8: 585 | M8: 14320 | N8: 65 | O8: 1.5
K9: MIKE | L9: 500 | M9: 5000 | N9: 50 | O9: 2.1
A10: WHO WORKED MORE THAN 70 HRS | K10: AISHU | L10: 480 | M10: 5000 | N10: 60 | O10: 1.8
K11: SURYA | L11: 450 | M11: 7744 | N11: 45 | O11: 1.1
B12: 70 | C12: =IFERROR(INDEX('DAILY WORKOUT LOG'!A3:A61,MATCH('MEMBER ANALYSIS'!B12,'DAILY WORKOUT LOG'!H3:H61,0)),"NO DATA") -> PRABHA | K12: ARCHANA | L12: 450 | M12: 12600 | N12: 45 | O12: 2.7
K13: PRAKASH | L13: 450 | M13: 8800 | N13: 45 | O13: 1
A14: FIND THE BMI CATEFORY OF LAVANYA | K14: KEERTHI | L14: 440 | M14: 10000 | N14: 55 | O14: 2.6
K15: VIJAY | L15: 420 | M15: 11000 | N15: 60 | O15: 1
B16: LAVANYA | C16: =VLOOKUP(B16,'DAILY WORKOUT LOG'!A2:P61,15,FALSE) -> NORMAL | K16: SANJAY | L16: 420 | M16: 12200 | N16: 60 | O16: 1.6
K17: NITHIYA | L17: 405 | M17: 4200 | N17: 45 | O17: 2.8
A18: WHO DRANK LESS THAN 2 LITRES WATER | K18: RIYA | L18: 400 | M18: 14570 | N18: 40 | O18: 2.2
K19: YASHNA | L19: 400 | M19: 10250 | N19: 40 | O19: 1.9
C20: =COUNTIF('DAILY WORKOUT LOG'!K3:K61,"<2") -> 24 | K20: KOMATHI | L20: 390 | M20: 5900 | N20: 65 | O20: 2.7
K21: SRIRAM | L21: 385 | M21: 7851 | N21: 55 | O21: 1.3
K22: PRATHIKSHA | L22: 384 | M22: 12100 | N22: 64 | O22: 1.9
K23: SIVA | L23: 360 | M23: 14000 | N23: 45 | O23: 2.4
A24: COMPARISON OF CALORIES BURNED VS STEPS FOR TOP 3 RANK | K24: NANCY | L24: 360 | M24: 9200 | N24: 60 | O24: 2.3
K25: DEV | L25: 350 | M25: 11240 | N25: 50 | O25: 2.2
B26: NAMES | C26: CALORIES BURNT | D26: STEPS | E26: DURATION | K26: AARAV | L26: 350 | M26: 12500 | N26: 50 | O26: 2.5
B27: KARTHICK | C27: 720 | D27: 12400 | E27: 72 | K27: NILA | L27: 333 | M27: 4600 | N27: 37 | O27: 2
B28: PRABHA | C28: 700 | D28: 11900 | E28: 70 | K28: ARYAN | L28: 330 | M28: 8900 | N28: 55 | O28: 1.9
B29: JILLU | C29: 620 | D29: 12800 | E29: 85 | K29: POOJA | L29: 330 | M29: 4500 | N29: 55 | O29: 2.5
K30: BANU | L30: 325 | M30: 7000 | N30: 65 | O30: 2.4
K31: AADHI | L31: 320 | M31: 10000 | N31: 40 | O31: 2
K32: ISHIKA | L32: 300 | M32: 4500 | N32: 60 | O32: 2.1
K33: DURAI | L33: 288 | M33: 5000 | N33: 48 | O33: 1.5
K34: ANU | L34: 288 | M34: 3700 | N34: 48 | O34: 2.2
K35: LAVANYA | L35: 280 | M35: 9700 | N35: 35 | O35: 1.3
K36: MEERA | L36: 280 | M36: 12200 | N36: 40 | O36: 2.4
K37: KABIR | L37: 270 | M37: 4571 | N37: 30 | O37: 1.8
K38: WILSON | L38: 270 | M38: 6455 | N38: 45 | O38: 1.1
K39: STEEVE | L39: 260 | M39: 13200 | N39: 65 | O39: 2.1
K40: TIPPU | L40: 250 | M40: 2475 | N40: 50 | O40: 2.3
...

Sheet FITNESS GOAL PLANNER
A1: MEMBER INFO | H1: GOAL SEEK SECTION [WEIGHT LOSS PLAN]
A3: 👤 MEMBER NAME | B3: KARTHICK | H3: 👤 MEMBER NAME | I3: RIYA
A4: 📏 CURRENT WEIGHT | B4: =INDEX(Table1[WEIGHT(Kg)],MATCH('FITNESS GOAL PLANNER'!B3,Table1[NAME],0)) -> 65 | H4: 📏 CURRENT WEIGHT | I4: =INDEX(Table1[WEIGHT(Kg)],MATCH('FITNESS GOAL PLANNER'!I3,Table1[NAME],0)) -> 58
A5: 🔥 CALORIES BURNED | B5: =INDEX(Table1[[CALORIES BURNT ]],MATCH('FITNESS GOAL PLANNER'!B3,Table1[NAME],0)) -> 720 | H5: 🔥 Calories Burned | I5: 21973.8
A6: 💧 WATER INTAKE | B6: =INDEX(Table1[WATER(L)],MATCH('FITNESS GOAL PLANNER'!B3,Table1[NAME],0)) -> 2 | H6: 🎯 Target Weight | I6: 45
A7: ⚖️BMI | B7: =INDEX(Table1[BMI],MATCH('FITNESS GOAL PLANNER'!B3,Table1[NAME],0)) -> 25 | H7: 1kg = Calories | I7: 7700
A8: 🟢 STATUS | B8: =INDEX(Table1[STATUS],MATCH('FITNESS GOAL PLANNER'!B3,Table1[NAME],0)) -> ACTIVE | H8: 🧮 Expected Weight | I8: =ROUND(I4-(I5/I7),0) -> 55
D13: FORECASTING
D15: DATE | E15: TOTAL STEPS
D16: 45833 | E16: =SUMIFS(Table1[STEPS],Table1[DATE],'FITNESS GOAL PLANNER'!D16) -> 76960
D17: 45834 | E17: =SUMIFS(Table1[STEPS],Table1[DATE],'FITNESS GOAL PLANNER'!D17) -> 68404
D18: 45835 | E18: =SUMIFS(Table1[STEPS],Table1[DATE],'FITNESS GOAL PLANNER'!D18) -> 94300
D19: 45836 | E19: =SUMIFS(Table1[STEPS],Table1[DATE],'FITNESS GOAL PLANNER'!D19) -> 74500
D20: 45837 | E20: =SUMIFS(Table1[STEPS],Table1[DATE],'FITNESS GOAL PLANNER'!D20) -> 82596
D21: 45838 | E21: =SUMIFS(Table1[STEPS],Table1[DATE],'FITNESS GOAL PLANNER'!D21) -> 83914
D22: 45839 | E22: =FORECAST(D22,$E$16:$E$21,$D$16:$D$21) -> 85866.933
D23: 45840 | E23: =FORECAST(D23,$E$16:$E$21,$D$16:$D$21) -> 87511.105
D24: 45841 | E24: =FORECAST(D24,$E$16:$E$21,$D$16:$D$21) -> 89155.276
D25: 45842 | E25: =FORECAST(D25,$E$16:$E$21,$D$16:$D$21) -> 90799.448
D26: 45843 | E26: =FORECAST(D26,$E$16:$E$21,$D$16:$D$21) -> 92443.619
D27: 45844 | E27: =FORECAST(D27,$E$16:$E$21,$D$16:$D$21) -> 94087.79

Sheet PIVOT TABLES
A1: TOTAL STEPS BY DAY | D1: CALORIES BURNT BY DAYS | G1: SUM OF DURATION BY WORKOUT TYPE
A3: DAYS | B3: TOTAL STEPS | D3: DAYS | E3: Sum of CALORIES BURNT | G3: DAYS | H3: Sum of DURATION
A4: Monday | B4: 83914 | D4: Monday | E4: 2925 | G4: CYCLING | H4: 283
A5: Wednesday | B5: 76960 | D5: Wednesday | E5: 2863 | G5: GYM | H5: 342
A6: Thursday | B6: 68404 | D6: Thursday | E6: 2258 | G6: PUSHUPS | H6: 242
A7: Friday | B7: 94300 | D7: Friday | E7: 3545 | G7: RUNNING | H7: 190
A8: Saturday | B8: 74500 | D8: Saturday | E8: 3252 | G8: SQUADS | H8: 270
A9: Sunday | B9: 82596 | D9: Sunday | E9: 2935 | G9: STRETCHING | H9: 193
A10: Grand Total | B10: 480674 | D10: Grand Total | E10: 17778 | G10: TREAD MILL | H10: 135
G11: TREAD MILL | H11: 45
A12: SPARK LINES | G12: WALKING | H12: 250
G13: WEIGHT LIFTING | H13: 244
G14: YOGA | H14: 325
A15: AVERAGE SLEEP BY STATUS | G15: Grand Total | H15: 2519
A17: STATUS | B17: Average of SLEEP(hrs)
A18: ACTIVE | B18: 5.9882353
A19: IN ACTIVE | B19: 5.804 | H19: KPI LAYOUT
A20: Grand Total | B20: 5.9101695
H21: A | J21: B
H22: 👣 | I22: Total Steps | J22: =SUM(Table1[STEPS]) -> 480674
H23: 😴 | I23: Average Sleep | J23: =AVERAGE(Table1[SLEEP(hrs)]) -> 5.9101695
H24: 🔥 | I24: Total Calories | J24: =SUM(Table1[[CALORIES BURNT ]]) -> 17778
H25: 👤 | I25: Active Users | J25: =COUNTIF(Table1[STATUS],"ACTIVE") -> 34
H26: ⚖️ | I26: Average BMI | J26: =AVERAGE(Table1[BMI]) -> 26.457627
H27: ⏱️ | I27: Workout Duration | J27: =SUM(Table1[DURATION]) -> 2519

Sheet  FITNESS DASHBOARD 
